127.0.0.1 - - [13/Jan/2019:18:25:22 +0800] "GET /Attribute HTTP/1.0" 200 523 "-" "Mozilla/5.0 (Windows NT 10.0; WOW64) AppleWebKit/537.36 (KHTML, like Gecko) Chrome/58.0.3029.110 Safari/537.36 SE 2.X MetaSr 1.0"
127.0.0.1 - - [13/Jan/2019:18:25:35 +0800] "POST /Attribute HTTP/1.0" 500 291 "http://129.211.104.220/Attribute" "Mozilla/5.0 (Windows NT 10.0; WOW64) AppleWebKit/537.36 (KHTML, like Gecko) Chrome/58.0.3029.110 Safari/537.36 SE 2.X MetaSr 1.0"
[2019-01-13 18:32:24 +0800] [4388] [INFO] Starting gunicorn 19.9.0
[2019-01-13 18:32:24 +0800] [4388] [ERROR] Connection in use: ('127.0.0.1', 5000)
[2019-01-13 18:32:24 +0800] [4388] [ERROR] Retrying in 1 second.
[2019-01-13 18:32:25 +0800] [4388] [ERROR] Connection in use: ('127.0.0.1', 5000)
[2019-01-13 18:32:25 +0800] [4388] [ERROR] Retrying in 1 second.
[2019-01-13 18:32:26 +0800] [4388] [ERROR] Connection in use: ('127.0.0.1', 5000)
[2019-01-13 18:32:26 +0800] [4388] [ERROR] Retrying in 1 second.
[2019-01-13 18:32:27 +0800] [4388] [ERROR] Connection in use: ('127.0.0.1', 5000)
[2019-01-13 18:32:27 +0800] [4388] [ERROR] Retrying in 1 second.
[2019-01-13 18:32:28 +0800] [4388] [ERROR] Connection in use: ('127.0.0.1', 5000)
[2019-01-13 18:32:28 +0800] [4388] [ERROR] Retrying in 1 second.
[2019-01-13 18:32:29 +0800] [4388] [ERROR] Can't connect to ('127.0.0.1', 5000)
127.0.0.1 - - [13/Jan/2019:18:32:35 +0800] "GET /index HTTP/1.0" 200 3665 "http://129.211.104.220/" "Mozilla/5.0 (Windows NT 10.0; WOW64) AppleWebKit/537.36 (KHTML, like Gecko) Chrome/58.0.3029.110 Safari/537.36 SE 2.X MetaSr 1.0"
127.0.0.1 - - [13/Jan/2019:18:32:37 +0800] "GET /Attribute HTTP/1.0" 200 523 "http://129.211.104.220/index" "Mozilla/5.0 (Windows NT 10.0; WOW64) AppleWebKit/537.36 (KHTML, like Gecko) Chrome/58.0.3029.110 Safari/537.36 SE 2.X MetaSr 1.0"
127.0.0.1 - - [13/Jan/2019:18:32:51 +0800] "POST /Attribute HTTP/1.0" 500 291 "http://129.211.104.220/Attribute" "Mozilla/5.0 (Windows NT 10.0; WOW64) AppleWebKit/537.36 (KHTML, like Gecko) Chrome/58.0.3029.110 Safari/537.36 SE 2.X MetaSr 1.0"
127.0.0.1 - - [13/Jan/2019:19:31:47 +0800] "GET / HTTP/1.0" 200 2848 "-" "Mozilla/5.0 (Windows NT 10.0; WOW64) AppleWebKit/537.36 (KHTML, like Gecko) Chrome/51.0.2704.103 Safari/537.36"
[2019-01-13 21:21:39 +0800] [20329] [INFO] Starting gunicorn 19.9.0
[2019-01-13 21:21:39 +0800] [20329] [ERROR] Connection in use: ('127.0.0.1', 5000)
[2019-01-13 21:21:39 +0800] [20329] [ERROR] Retrying in 1 second.
[2019-01-13 21:21:40 +0800] [20329] [ERROR] Connection in use: ('127.0.0.1', 5000)
[2019-01-13 21:21:40 +0800] [20329] [ERROR] Retrying in 1 second.
[2019-01-13 21:21:41 +0800] [20329] [ERROR] Connection in use: ('127.0.0.1', 5000)
[2019-01-13 21:21:41 +0800] [20329] [ERROR] Retrying in 1 second.
[2019-01-13 21:21:42 +0800] [20329] [ERROR] Connection in use: ('127.0.0.1', 5000)
[2019-01-13 21:21:42 +0800] [20329] [ERROR] Retrying in 1 second.
[2019-01-13 21:21:43 +0800] [20329] [ERROR] Connection in use: ('127.0.0.1', 5000)
[2019-01-13 21:21:43 +0800] [20329] [ERROR] Retrying in 1 second.
[2019-01-13 21:21:44 +0800] [20329] [ERROR] Can't connect to ('127.0.0.1', 5000)
[2019-01-13 21:26:56 +0800] [20752] [INFO] Starting gunicorn 19.9.0
[2019-01-13 21:26:56 +0800] [20752] [ERROR] Connection in use: ('127.0.0.1', 5000)
[2019-01-13 21:26:56 +0800] [20752] [ERROR] Retrying in 1 second.
[2019-01-13 21:26:57 +0800] [20752] [ERROR] Connection in use: ('127.0.0.1', 5000)
[2019-01-13 21:26:57 +0800] [20752] [ERROR] Retrying in 1 second.
[2019-01-13 21:26:58 +0800] [20752] [ERROR] Connection in use: ('127.0.0.1', 5000)
[2019-01-13 21:26:58 +0800] [20752] [ERROR] Retrying in 1 second.
[2019-01-13 21:26:59 +0800] [20752] [ERROR] Connection in use: ('127.0.0.1', 5000)
[2019-01-13 21:26:59 +0800] [20752] [ERROR] Retrying in 1 second.
[2019-01-13 21:27:00 +0800] [20752] [ERROR] Connection in use: ('127.0.0.1', 5000)
[2019-01-13 21:27:00 +0800] [20752] [ERROR] Retrying in 1 second.
[2019-01-13 21:27:01 +0800] [20752] [ERROR] Can't connect to ('127.0.0.1', 5000)
[2019-01-13 21:27:09 +0800] [20790] [INFO] Starting gunicorn 19.9.0
[2019-01-13 21:27:09 +0800] [20790] [ERROR] Connection in use: ('127.0.0.1', 5000)
[2019-01-13 21:27:09 +0800] [20790] [ERROR] Retrying in 1 second.
[2019-01-13 21:27:10 +0800] [20790] [ERROR] Connection in use: ('127.0.0.1', 5000)
[2019-01-13 21:27:10 +0800] [20790] [ERROR] Retrying in 1 second.
[2019-01-13 21:27:11 +0800] [20790] [ERROR] Connection in use: ('127.0.0.1', 5000)
[2019-01-13 21:27:11 +0800] [20790] [ERROR] Retrying in 1 second.
[2019-01-13 21:27:12 +0800] [20790] [ERROR] Connection in use: ('127.0.0.1', 5000)
[2019-01-13 21:27:12 +0800] [20790] [ERROR] Retrying in 1 second.
[2019-01-13 21:27:13 +0800] [20790] [ERROR] Connection in use: ('127.0.0.1', 5000)
[2019-01-13 21:27:13 +0800] [20790] [ERROR] Retrying in 1 second.
[2019-01-13 21:27:14 +0800] [20790] [ERROR] Can't connect to ('127.0.0.1', 5000)
[2019-01-13 21:27:25 +0800] [20813] [INFO] Starting gunicorn 19.9.0
[2019-01-13 21:27:25 +0800] [20813] [ERROR] Connection in use: ('127.0.0.1', 5000)
[2019-01-13 21:27:25 +0800] [20813] [ERROR] Retrying in 1 second.
[2019-01-13 21:27:26 +0800] [20813] [ERROR] Connection in use: ('127.0.0.1', 5000)
[2019-01-13 21:27:26 +0800] [20813] [ERROR] Retrying in 1 second.
[2019-01-13 21:27:27 +0800] [20813] [ERROR] Connection in use: ('127.0.0.1', 5000)
[2019-01-13 21:27:27 +0800] [20813] [ERROR] Retrying in 1 second.
[2019-01-13 21:27:28 +0800] [20813] [ERROR] Connection in use: ('127.0.0.1', 5000)
[2019-01-13 21:27:28 +0800] [20813] [ERROR] Retrying in 1 second.
[2019-01-13 21:27:29 +0800] [20813] [ERROR] Connection in use: ('127.0.0.1', 5000)
[2019-01-13 21:27:29 +0800] [20813] [ERROR] Retrying in 1 second.
[2019-01-13 21:27:30 +0800] [20813] [ERROR] Can't connect to ('127.0.0.1', 5000)
[2019-01-13 22:51:33 +0800] [28894] [INFO] Starting gunicorn 19.9.0
[2019-01-13 22:51:33 +0800] [28894] [INFO] Listening at: http://127.0.0.1:5000 (28894)
[2019-01-13 22:51:33 +0800] [28894] [INFO] Using worker: sync
[2019-01-13 22:51:33 +0800] [28897] [INFO] Booting worker with pid: 28897
[2019-01-13 22:51:33 +0800] [28899] [INFO] Booting worker with pid: 28899
[2019-01-13 22:51:33 +0800] [28901] [INFO] Booting worker with pid: 28901
[2019-01-13 22:51:33 +0800] [28902] [INFO] Booting worker with pid: 28902
[2019-01-13 22:52:49 +0800] [28902] [ERROR] Error handling request /Market_cquisition
Traceback (most recent call last):
  File "/home/ubuntu/.local/lib/python3.5/site-packages/gunicorn/workers/sync.py", line 135, in handle
    self.handle_request(listener, req, client, addr)
  File "/home/ubuntu/.local/lib/python3.5/site-packages/gunicorn/workers/sync.py", line 176, in handle_request
    respiter = self.wsgi(environ, resp.start_response)
  File "/home/ubuntu/.local/lib/python3.5/site-packages/flask/app.py", line 2309, in __call__
    return self.wsgi_app(environ, start_response)
  File "/home/ubuntu/.local/lib/python3.5/site-packages/flask/app.py", line 2303, in wsgi_app
    ctx.auto_pop(error)
  File "/home/ubuntu/.local/lib/python3.5/site-packages/flask/ctx.py", line 434, in auto_pop
    self.pop(exc)
  File "/home/ubuntu/.local/lib/python3.5/site-packages/flask/ctx.py", line 423, in pop
    app_ctx.pop(exc)
  File "/home/ubuntu/.local/lib/python3.5/site-packages/flask/ctx.py", line 231, in pop
    self.app.do_teardown_appcontext(exc)
  File "/home/ubuntu/.local/lib/python3.5/site-packages/flask/app.py", line 2166, in do_teardown_appcontext
    func(exc)
  File "/home/ubuntu/.local/lib/python3.5/site-packages/flask_sqlalchemy/__init__.py", line 805, in shutdown_session
    self.session.commit()
  File "/home/ubuntu/.local/lib/python3.5/site-packages/sqlalchemy/orm/scoping.py", line 153, in do
    return getattr(self.registry(), name)(*args, **kwargs)
  File "/home/ubuntu/.local/lib/python3.5/site-packages/sqlalchemy/orm/session.py", line 954, in commit
    self.transaction.commit()
  File "/home/ubuntu/.local/lib/python3.5/site-packages/sqlalchemy/orm/session.py", line 465, in commit
    self._assert_active(prepared_ok=True)
  File "/home/ubuntu/.local/lib/python3.5/site-packages/sqlalchemy/orm/session.py", line 276, in _assert_active
    % self._rollback_exception
sqlalchemy.exc.InvalidRequestError: This Session's transaction has been rolled back due to a previous exception during flush. To begin a new transaction with this Session, first issue Session.rollback(). Original exception was: (pymysql.err.InternalError) (1366, "Incorrect string value: '\\xE8\\xA1\\x8C\\xE4\\xB8\\x9A...' for column 'Industry_composition' at row 1") [SQL: 'INSERT INTO industry_composition (`cateID`, `Industry_composition`, date, `cateName`, `tradeIndex`, `tradeGrowthRange`, `payAmtParentCateRate`, `payCntParentCateRate`, `Payment_amount`) VALUES (%(cateID)s, %(Industry_composition)s, %(date)s, %(cateName)s, %(tradeIndex)s, %(tradeGrowthRange)s, %(payAmtParentCateRate)s, %(payCntParentCateRate)s, %(Payment_amount)s)'] [parameters: {'date': '2018-05-01', 'cateName': '奶瓶', 'payCntParentCateRate': '0.6199', 'Payment_amount': '52845729', 'cateID': '50016455', 'tradeIndex': '1950259.8744166428', 'payAmtParentCateRate': '0.7956', 'tradeGrowthRange': '0.1235', 'Industry_composition': '行业构成'}] (Background on this error at: http://sqlalche.me/e/2j85)
[2019-01-13 23:30:38 +0800] [28902] [ERROR] Error handling request /Market_cquisition
Traceback (most recent call last):
  File "/home/ubuntu/.local/lib/python3.5/site-packages/gunicorn/workers/sync.py", line 135, in handle
    self.handle_request(listener, req, client, addr)
  File "/home/ubuntu/.local/lib/python3.5/site-packages/gunicorn/workers/sync.py", line 176, in handle_request
    respiter = self.wsgi(environ, resp.start_response)
  File "/home/ubuntu/.local/lib/python3.5/site-packages/flask/app.py", line 2309, in __call__
    return self.wsgi_app(environ, start_response)
  File "/home/ubuntu/.local/lib/python3.5/site-packages/flask/app.py", line 2303, in wsgi_app
    ctx.auto_pop(error)
  File "/home/ubuntu/.local/lib/python3.5/site-packages/flask/ctx.py", line 434, in auto_pop
    self.pop(exc)
  File "/home/ubuntu/.local/lib/python3.5/site-packages/flask/ctx.py", line 423, in pop
    app_ctx.pop(exc)
  File "/home/ubuntu/.local/lib/python3.5/site-packages/flask/ctx.py", line 231, in pop
    self.app.do_teardown_appcontext(exc)
  File "/home/ubuntu/.local/lib/python3.5/site-packages/flask/app.py", line 2166, in do_teardown_appcontext
    func(exc)
  File "/home/ubuntu/.local/lib/python3.5/site-packages/flask_sqlalchemy/__init__.py", line 805, in shutdown_session
    self.session.commit()
  File "/home/ubuntu/.local/lib/python3.5/site-packages/sqlalchemy/orm/scoping.py", line 153, in do
    return getattr(self.registry(), name)(*args, **kwargs)
  File "/home/ubuntu/.local/lib/python3.5/site-packages/sqlalchemy/orm/session.py", line 954, in commit
    self.transaction.commit()
  File "/home/ubuntu/.local/lib/python3.5/site-packages/sqlalchemy/orm/session.py", line 465, in commit
    self._assert_active(prepared_ok=True)
  File "/home/ubuntu/.local/lib/python3.5/site-packages/sqlalchemy/orm/session.py", line 276, in _assert_active
    % self._rollback_exception
sqlalchemy.exc.InvalidRequestError: This Session's transaction has been rolled back due to a previous exception during flush. To begin a new transaction with this Session, first issue Session.rollback(). Original exception was: (pymysql.err.InternalError) (1366, "Incorrect string value: '\\xE8\\xA1\\x8C\\xE4\\xB8\\x9A...' for column 'Industry_composition' at row 1") [SQL: 'INSERT INTO industry_composition (`cateID`, `Industry_composition`, date, `cateName`, `tradeIndex`, `tradeGrowthRange`, `payAmtParentCateRate`, `payCntParentCateRate`, `Payment_amount`) VALUES (%(cateID)s, %(Industry_composition)s, %(date)s, %(cateName)s, %(tradeIndex)s, %(tradeGrowthRange)s, %(payAmtParentCateRate)s, %(payCntParentCateRate)s, %(Payment_amount)s)'] [parameters: {'date': '2018-05-01', 'cateName': '奶瓶', 'payCntParentCateRate': '0.6199', 'Payment_amount': '52845729', 'cateID': '50016455', 'tradeIndex': '1950259.8744166428', 'payAmtParentCateRate': '0.7956', 'tradeGrowthRange': '0.1235', 'Industry_composition': '行业构成'}] (Background on this error at: http://sqlalche.me/e/2j85)
[2019-01-13 23:31:16 +0800] [28902] [ERROR] Error handling request /Market_cquisition
Traceback (most recent call last):
  File "/home/ubuntu/.local/lib/python3.5/site-packages/gunicorn/workers/sync.py", line 135, in handle
    self.handle_request(listener, req, client, addr)
  File "/home/ubuntu/.local/lib/python3.5/site-packages/gunicorn/workers/sync.py", line 176, in handle_request
    respiter = self.wsgi(environ, resp.start_response)
  File "/home/ubuntu/.local/lib/python3.5/site-packages/flask/app.py", line 2309, in __call__
    return self.wsgi_app(environ, start_response)
  File "/home/ubuntu/.local/lib/python3.5/site-packages/flask/app.py", line 2303, in wsgi_app
    ctx.auto_pop(error)
  File "/home/ubuntu/.local/lib/python3.5/site-packages/flask/ctx.py", line 434, in auto_pop
    self.pop(exc)
  File "/home/ubuntu/.local/lib/python3.5/site-packages/flask/ctx.py", line 423, in pop
    app_ctx.pop(exc)
  File "/home/ubuntu/.local/lib/python3.5/site-packages/flask/ctx.py", line 231, in pop
    self.app.do_teardown_appcontext(exc)
  File "/home/ubuntu/.local/lib/python3.5/site-packages/flask/app.py", line 2166, in do_teardown_appcontext
    func(exc)
  File "/home/ubuntu/.local/lib/python3.5/site-packages/flask_sqlalchemy/__init__.py", line 805, in shutdown_session
    self.session.commit()
  File "/home/ubuntu/.local/lib/python3.5/site-packages/sqlalchemy/orm/scoping.py", line 153, in do
    return getattr(self.registry(), name)(*args, **kwargs)
  File "/home/ubuntu/.local/lib/python3.5/site-packages/sqlalchemy/orm/session.py", line 954, in commit
    self.transaction.commit()
  File "/home/ubuntu/.local/lib/python3.5/site-packages/sqlalchemy/orm/session.py", line 465, in commit
    self._assert_active(prepared_ok=True)
  File "/home/ubuntu/.local/lib/python3.5/site-packages/sqlalchemy/orm/session.py", line 276, in _assert_active
    % self._rollback_exception
sqlalchemy.exc.InvalidRequestError: This Session's transaction has been rolled back due to a previous exception during flush. To begin a new transaction with this Session, first issue Session.rollback(). Original exception was: (pymysql.err.InternalError) (1366, "Incorrect string value: '\\xE8\\xA1\\x8C\\xE4\\xB8\\x9A...' for column 'Industry_composition' at row 1") [SQL: 'INSERT INTO industry_composition (`cateID`, `Industry_composition`, date, `cateName`, `tradeIndex`, `tradeGrowthRange`, `payAmtParentCateRate`, `payCntParentCateRate`, `Payment_amount`) VALUES (%(cateID)s, %(Industry_composition)s, %(date)s, %(cateName)s, %(tradeIndex)s, %(tradeGrowthRange)s, %(payAmtParentCateRate)s, %(payCntParentCateRate)s, %(Payment_amount)s)'] [parameters: {'date': '2018-05-01', 'cateName': '奶瓶', 'payCntParentCateRate': '0.6199', 'Payment_amount': '52845729', 'cateID': '50016455', 'tradeIndex': '1950259.8744166428', 'payAmtParentCateRate': '0.7956', 'tradeGrowthRange': '0.1235', 'Industry_composition': '行业构成'}] (Background on this error at: http://sqlalche.me/e/2j85)
[2019-01-13 23:32:26,686] ERROR in app: Exception on /Market_distribution [POST]
Traceback (most recent call last):
  File "/home/ubuntu/.local/lib/python3.5/site-packages/flask/app.py", line 2292, in wsgi_app
    response = self.full_dispatch_request()
  File "/home/ubuntu/.local/lib/python3.5/site-packages/flask/app.py", line 1816, in full_dispatch_request
    return self.finalize_request(rv)
  File "/home/ubuntu/.local/lib/python3.5/site-packages/flask/app.py", line 1831, in finalize_request
    response = self.make_response(rv)
  File "/home/ubuntu/.local/lib/python3.5/site-packages/flask/app.py", line 1957, in make_response
    'The view function did not return a valid response. The'
TypeError: The view function did not return a valid response. The function either returned None or ended without a return statement.
[2019-01-13 23:32:36,293] ERROR in app: Exception on /Market_distribution [POST]
Traceback (most recent call last):
  File "/home/ubuntu/.local/lib/python3.5/site-packages/flask/app.py", line 2292, in wsgi_app
    response = self.full_dispatch_request()
  File "/home/ubuntu/.local/lib/python3.5/site-packages/flask/app.py", line 1816, in full_dispatch_request
    return self.finalize_request(rv)
  File "/home/ubuntu/.local/lib/python3.5/site-packages/flask/app.py", line 1831, in finalize_request
    response = self.make_response(rv)
  File "/home/ubuntu/.local/lib/python3.5/site-packages/flask/app.py", line 1957, in make_response
    'The view function did not return a valid response. The'
TypeError: The view function did not return a valid response. The function either returned None or ended without a return statement.
[2019-01-13 23:43:16 +0800] [1025] [INFO] Booting worker with pid: 1025
[2019-01-13 23:43:30 +0800] [1049] [INFO] Booting worker with pid: 1049
[2019-01-13 23:49:53 +0800] [1678] [INFO] Booting worker with pid: 1678
[2019-01-13 23:50:04 +0800] [1705] [INFO] Booting worker with pid: 1705
[2019-01-13 23:52:57 +0800] [2042] [INFO] Booting worker with pid: 2042
[2019-01-13 23:53:07 +0800] [2076] [INFO] Booting worker with pid: 2076
[2019-01-13 23:59:08 +0800] [2606] [INFO] Booting worker with pid: 2606
[2019-01-13 23:59:20 +0800] [2622] [INFO] Booting worker with pid: 2622
[2019-01-14 00:04:58 +0800] [2042] [INFO] Parent changed, shutting down: <Worker 2042>
[2019-01-14 00:04:58 +0800] [2042] [INFO] Worker exiting (pid: 2042)
[2019-01-14 00:05:06 +0800] [1705] [INFO] Parent changed, shutting down: <Worker 1705>
[2019-01-14 00:05:06 +0800] [1705] [INFO] Worker exiting (pid: 1705)
[2019-01-14 00:05:06 +0800] [2622] [INFO] Parent changed, shutting down: <Worker 2622>
[2019-01-14 00:05:06 +0800] [2622] [INFO] Worker exiting (pid: 2622)
[2019-01-14 00:05:09 +0800] [2076] [INFO] Parent changed, shutting down: <Worker 2076>
[2019-01-14 00:05:09 +0800] [2076] [INFO] Worker exiting (pid: 2076)
[2019-01-14 14:44:11 +0800] [16866] [INFO] Starting gunicorn 19.9.0
[2019-01-14 14:44:11 +0800] [16866] [INFO] Listening at: http://127.0.0.1:8000 (16866)
[2019-01-14 14:44:11 +0800] [16866] [INFO] Using worker: sync
[2019-01-14 14:44:11 +0800] [16870] [INFO] Booting worker with pid: 16870
[2019-01-14 14:44:11 +0800] [16871] [INFO] Booting worker with pid: 16871
[2019-01-14 14:44:11 +0800] [16872] [INFO] Booting worker with pid: 16872
[2019-01-14 14:44:11 +0800] [16873] [INFO] Booting worker with pid: 16873
[2019-01-14 14:44:33 +0800] [16866] [INFO] Handling signal: int
[2019-01-14 14:44:34 +0800] [16871] [INFO] Worker exiting (pid: 16871)
[2019-01-14 14:44:34 +0800] [16870] [INFO] Worker exiting (pid: 16870)
[2019-01-14 14:44:34 +0800] [16872] [INFO] Worker exiting (pid: 16872)
[2019-01-14 14:44:34 +0800] [16873] [INFO] Worker exiting (pid: 16873)
[2019-01-14 14:44:35 +0800] [16866] [INFO] Shutting down: Master
[2019-01-14 14:46:55 +0800] [17136] [INFO] Starting gunicorn 19.9.0
[2019-01-14 14:46:55 +0800] [17136] [INFO] Listening at: http://127.0.0.1:8000 (17136)
[2019-01-14 14:46:55 +0800] [17136] [INFO] Using worker: sync
[2019-01-14 14:46:55 +0800] [17139] [INFO] Booting worker with pid: 17139
[2019-01-14 14:46:55 +0800] [17140] [INFO] Booting worker with pid: 17140
[2019-01-14 14:46:55 +0800] [17142] [INFO] Booting worker with pid: 17142
[2019-01-14 14:46:55 +0800] [17143] [INFO] Booting worker with pid: 17143
[2019-01-14 14:47:40 +0800] [17136] [INFO] Handling signal: int
[2019-01-14 14:47:40 +0800] [17139] [INFO] Worker exiting (pid: 17139)
[2019-01-14 14:47:40 +0800] [17140] [INFO] Worker exiting (pid: 17140)
[2019-01-14 14:47:40 +0800] [17142] [INFO] Worker exiting (pid: 17142)
[2019-01-14 14:47:40 +0800] [17143] [INFO] Worker exiting (pid: 17143)
[2019-01-14 14:47:41 +0800] [17136] [INFO] Shutting down: Master
[2019-01-14 14:50:54 +0800] [17543] [INFO] Starting gunicorn 19.9.0
[2019-01-14 14:50:54 +0800] [17543] [INFO] Listening at: http://127.0.0.1:8000 (17543)
[2019-01-14 14:50:54 +0800] [17543] [INFO] Using worker: sync
[2019-01-14 14:50:54 +0800] [17546] [INFO] Booting worker with pid: 17546
[2019-01-14 14:50:54 +0800] [17547] [INFO] Booting worker with pid: 17547
[2019-01-14 14:50:54 +0800] [17548] [INFO] Booting worker with pid: 17548
[2019-01-14 14:50:54 +0800] [17558] [INFO] Booting worker with pid: 17558
[2019-01-14 14:51:10 +0800] [17543] [INFO] Handling signal: int
[2019-01-14 14:51:10 +0800] [17547] [INFO] Worker exiting (pid: 17547)
[2019-01-14 14:51:10 +0800] [17546] [INFO] Worker exiting (pid: 17546)
[2019-01-14 14:51:10 +0800] [17548] [INFO] Worker exiting (pid: 17548)
[2019-01-14 14:51:10 +0800] [17558] [INFO] Worker exiting (pid: 17558)
[2019-01-14 14:51:11 +0800] [17543] [INFO] Shutting down: Master
[2019-01-14 14:51:19 +0800] [17607] [INFO] Starting gunicorn 19.9.0
[2019-01-14 14:51:19 +0800] [17607] [INFO] Listening at: http://127.0.0.1:5000 (17607)
[2019-01-14 14:51:19 +0800] [17607] [INFO] Using worker: sync
[2019-01-14 14:51:19 +0800] [17610] [INFO] Booting worker with pid: 17610
[2019-01-14 14:51:19 +0800] [17611] [INFO] Booting worker with pid: 17611
[2019-01-14 14:51:19 +0800] [17613] [INFO] Booting worker with pid: 17613
[2019-01-14 14:51:19 +0800] [17614] [INFO] Booting worker with pid: 17614
[2019-01-14 14:51:51 +0800] [17607] [INFO] Handling signal: int
[2019-01-14 14:51:52 +0800] [17610] [INFO] Worker exiting (pid: 17610)
[2019-01-14 14:51:52 +0800] [17611] [INFO] Worker exiting (pid: 17611)
[2019-01-14 14:51:52 +0800] [17614] [INFO] Worker exiting (pid: 17614)
[2019-01-14 14:51:52 +0800] [17613] [INFO] Worker exiting (pid: 17613)
[2019-01-14 14:51:53 +0800] [17607] [INFO] Shutting down: Master
